#VRML_SIM R2020a utf8
WorldInfo {
  contactProperties [
    ContactProperties {
      coulombFriction [
        1.5
      ]
    }
  ]
}
PointLight {
  attenuation 4 2 1
  intensity 6
  location 0 2 0
}
Viewpoint {
  orientation -0.4930321706840214 0.8112034061090547 0.3144333197796792 1.4917005464331645
  position 28.462416530527832 30.699647446060148 1.7442080551765495
}
TexturedBackground {
}
TexturedBackgroundLight {
  castShadows FALSE
}
Wall {
  translation 0.02 0 7.45
  size 20 2.4 0.2
}
Wall {
  translation -10.08 0 1.71042e-05
  rotation 0 1 0 1.5707996938995747
  name "wall(2)"
  size 15 2.4 0.2
}
Wall {
  translation 9.83 0 -1.62612e-05
  rotation 0 1 0 1.5707996938995747
  name "wall(3)"
  size 15 2.4 0.2
}
Solid {
  translation 8.73045018512769 -38495726.11220839 3.3188523806644774
  rotation 0.9999999887677951 0.00013222944775187254 7.056757784043337e-05 1.9608758326155484
  children [
    DEF tt Shape {
      appearance CementTiles {
      }
      geometry Box {
        size 2.5 1 0.8
      }
    }
  ]
  boundingObject USE tt
  physics Physics {
  }
  linearVelocity 0 -795.4732800000423 0
}
Wall {
  translation 0.03 0 -5.04
  rotation 0 1 0 1.5707996938995747
  name "wall(4)"
  size 5 2.4 0.2
}
Wall {
  translation -6.75994 0 -2.63
  rotation 0 1 0 -3.1415853071795863
  name "wall(6)"
  size 6.8 2.4 0.2
}
Wall {
  translation -8.20005 0 1.1
  rotation 0 1 0 -3.1415853071795863
  name "wall(7)"
  size 3.5 2.4 0.2
}
Wall {
  translation -1.5 0 1.1
  rotation 0 1 0 -3.1415853071795863
  name "wall(11)"
  size 5.6 2.4 0.2
}
Wall {
  translation 7.9 0 2.68
  rotation 3.23947e-08 -1 8.77262e-08 3.14159
  name "wall(16)"
  size 3.8 2.4 0.2
}
Wall {
  translation 3.11995 0 1.1
  rotation 0 1 0 -3.1415853071795863
  name "wall(14)"
  size 0.4 2.4 0.2
}
Wall {
  translation 2.3 0 3.3
  rotation 0 1 0 -3.1415853071795863
  name "wall(17)"
  size 1.9 2.4 0.2
}
Wall {
  translation 1.6 0 1.1
  rotation 0 1 0 -3.1415853071795863
  name "wall(15)"
  size 0.6 2.4 0.2
}
Wall {
  translation -4.35005 0 4.3
  rotation 0 -1 0 1.57079
  name "wall(10)"
  size 6.6 2.4 0.2
}
Wall {
  translation 3.4 0 4.2
  rotation 0 -1 0 1.57079
  name "wall(13)"
  size 6.3 2.4 0.2
}
Wall {
  translation 1.2 0 5.3
  rotation 0 -1 0 1.57079
  name "wall(12)"
  size 4.3 2.4 0.3
}
Wall {
  translation -6.56005 0 0.4
  rotation 0 -1 0 1.57079
  name "wall(8)"
  size 1.4 2.4 0.2
}
Wall {
  translation -6.63005 0 -2.04001
  rotation 0 -1 0 1.57079
  name "wall(9)"
}
Wall {
  translation -1.07005 0 -2.63
  rotation 0 1 0 -3.1415853071795863
  name "wall(5)"
  size 2 2.4 0.2
}
Bed {
  translation -8.7 0.01 -6.71
  rotation 0 1 0 3.14159
}
Fridge {
  hidden position_0_0 -6.76373086126995e-08
  hidden position_0_1 2.2448619066543829e-07
  hidden rotation_1 0 -0.9999999999999999 0 6.664001874625056e-08
  hidden rotation_2 0 1 0 2.2500259981366257e-07
  translation 6.03 0 7.07
  rotation 0 1 0 1.5708
}
Chair {
  hidden linearVelocity_0 2.0759435070337212e-17 1.0732655376016037e-15 -1.3724919328537684e-16
  hidden angularVelocity_0 -2.894198453772122e-16 -2.361701704266472e-17 2.6037638476800835e-17
  translation 8.08019012179141 -0.004489055999999936 -0.5305830000235127
  rotation 0.0037116891855764026 0.9999931116579032 -3.6624678969603263e-07 -3.1413953071810288
  color 0.894118 0.447059 0
  physics Physics {
  }
}
Chair {
  hidden linearVelocity_0 3.871868539960872e-17 9.54016699250814e-16 6.1389907005205846e-18
  hidden angularVelocity_0 2.6382015698509194e-17 2.6378718667224745e-17 -5.201699534492645e-17
  translation -2.9999999999357447 -0.004489055999999936 3.199999999999987
  rotation 0.0037116891855764693 0.9999931116579033 -3.6624678957260474e-07 -3.1413953071810266
  name "chair(6)"
  color 0.894118 0.447059 0
  physics Physics {
  }
}
Chair {
  hidden linearVelocity_0 -1.4551119260320993e-16 1.112794026446103e-15 -5.469668157180484e-17
  hidden angularVelocity_0 -5.049807923655027e-17 4.382649112885109e-17 3.3340932953556095e-16
  translation -4.000000201684752 -0.004489056000000269 -6.099999784580705
  rotation 0.003711663628787548 0.9999862262180014 0.00371092001896122 1.5710104648193417
  name "chair(7)"
  color 0.894118 0.447059 0
  physics Physics {
  }
}
Chair {
  hidden linearVelocity_0 9.306656222001853e-17 1.4707737780359586e-15 9.82168739776378e-17
  hidden angularVelocity_0 1.7289670187706897e-16 4.662355697085548e-18 -1.6835001829547448e-16
  translation 7.2 -0.004489056000000158 0.6599209999999995
  rotation 0.0037116636187321445 0.9999862235088895 0.0037116499849376423 1.5708137766177488
  name "chair(2)"
  color 0.894118 0.447059 0
  physics Physics {
  }
}
Chair {
  hidden linearVelocity_0 3.733087347517083e-17 -7.950128512001113e-16 -8.216999274905426e-17
  hidden angularVelocity_0 -9.509322001398643e-17 3.067947402166418e-17 -6.524822583806038e-17
  translation 6.220000379879218 -0.004489055999999714 -1.5499210517594384
  rotation 0.003711663618515834 0.9999862234506545 -0.0037116656747303352 -1.5708095494520335
  name "chair(3)"
  color 0.894118 0.447059 0
  physics Physics {
  }
}
Chair {
  hidden linearVelocity_0 -1.0498382171328177e-16 1.3117712044801886e-15 1.238105575341192e-16
  hidden angularVelocity_0 2.0747611705207233e-16 2.4132884168480266e-18 2.0669187936218404e-16
  translation 7.190000000094691 -0.004489056000000158 -1.5499212450960091
  rotation 0.003711663618491932 0.9999862234442396 -0.0037116674029959856 -1.5708090838214406
  name "chair(5)"
  color 0.894118 0.447059 0
  physics Physics {
  }
}
Chair {
  hidden linearVelocity_0 -7.331809348355213e-17 -1.2720205619201827e-15 -1.0849199856681703e-16
  hidden angularVelocity_0 -3.1985901749823573e-16 -6.159360737148786e-17 9.566482136132621e-17
  translation 6.1899999996588875 -0.004489055999999603 0.6799212450960139
  rotation 0.003711663618732158 0.9999862235088895 0.0037116499849376323 1.5708137766177477
  name "chair(4)"
  color 0.894118 0.447059 0
  physics Physics {
  }
}
Table {
  translation 6.7 -0.27 -0.53
  size 1.8 1 1
  frameThickness 0.1
}
Table {
  translation -3.7 -0.27 3.4
  rotation 0 1 0 1.5708
  name "table(1)"
  size 1.8 1 1
  frameThickness 0.1
}
Table {
  translation -4 -0.27 -6.9
  rotation 0 1 0 -3.1415853071795863
  name "table(2)"
  size 1.8 1 1
  frameThickness 0.1
}
Cabinet {
  hidden translation_6 -0.17500000000283933 1.269966298528139 0.49999999996760636
  hidden rotation_6 0.9956950121395586 1.3581259780646693e-08 -0.09269003614415246 1.2119448386464555e-05
  hidden position_6_0 -1.1307525838908722e-05
  hidden translation_7 -1.9083179481071966e-11 0 3.3752964628423258e-06
  hidden rotation_7 0 -1 0 1.1307536820348241e-05
  hidden translation_10 0.3000000000016829 1.2699662985563493 0.4999999999685314
  hidden rotation_10 -0.9985288269951694 1.9365013773172047e-09 -0.05422344197532049 -1.2084992098250589e-05
  hidden position_10_0 6.892103889634341e-06
  hidden translation_11 4.135525255577477e-12 0 1.2000875897730789e-06
  hidden rotation_11 0 1 0 6.892072987427614e-06
  hidden translation_14 0.3899999999999988 0.6699656277433873 0.4999999999046687
  hidden rotation_14 1 6.991849950895302e-14 -1.3597115621705238e-12 1.2169091177553724e-05
  hidden position_14_0 2.2503548717969277e-05
  hidden translation_15 0 0 2.2503548717969277e-05
  hidden translation_22 0.21499999999999808 0.4199656277413173 0.4999999999046816
  hidden rotation_22 1 6.602057783329614e-14 1.6456549433170656e-12 1.2169096012826431e-05
  hidden position_22_0 2.2502263080741517e-05
  hidden translation_23 0 0 2.2502263080741517e-05
  hidden translation_30 0.3899999999999988 0.4199656277398382 0.4999999999046816
  hidden rotation_30 0.9999999999999999 6.59509538469766e-14 -2.9314879566273893e-12 1.2169099470351232e-05
  hidden position_30_0 2.2502259869614945e-05
  hidden translation_31 0 0 2.2502259869614945e-05
  hidden translation_38 0 0.19492859188291856 0.49999999922571003
  hidden rotation_38 1 6.186436438034986e-14 -1.002695773143181e-12 2.5432471752138733e-05
  hidden position_38_0 6.427045603902025e-05
  hidden translation_39 0 0 6.427045603902025e-05
  translation -9.38 0 -2.75
  rotation 0 -1 0 3.14159
  innerThickness 0.01
  outerThickness 0.07
  rowsHeights [
    0.25, 0.2, 0.3, 0.5, 0.4
  ]
  columnsWidths [
    0.6, 0.18, 0.17
  ]
  handle CabinetHandle {
    handleColor 0.666667 0.333333 0
  }
  primaryAppearance PaintedWood {
    colorOverride 0.666667 0.333333 0
  }
  secondaryAppearance PaintedWood {
    colorOverride 0.666667 0.333333 0
  }
}
Door {
  hidden translation_5 8.485934177571153e-11 -2.220446049250313e-16 0.0010000002705241595
  translation 2.42 0 1.1
  position -1.867471723448389e-08
}
Bed {
  translation -3.1 0.02 6.41
  rotation 0 1 0 3.14159
  name "bed(1)"
}
Bed {
  translation -8.85 0.01 6.42
  rotation 0 1 0 3.14159
  name "bed(2)"
}
Wall {
  translation 0 0 -7.58
  name "wall(1)"
  size 20 2.3 0.2
}
Toilet {
  translation -9.39 0 -0.799977
  rotation 0 1 0 1.5708
}
Toilet {
  translation 2.25 0 6.93001
  rotation 0 1 0 -3.1415853071795863
  name "toilet(1)"
}
Sofa {
  hidden linearVelocity_0 9.002278735559098e-18 4.001776687800885e-16 -7.551312353454636e-17
  hidden angularVelocity_0 -2.3713721683916195e-16 5.493235075196588e-18 9.781427517898017e-18
  translation 0.77 -0.009809999999999985 -5.73
  rotation -7.368702411445836e-15 -6.941855834964704e-14 -1 -0.0043851110224328105
  physics Physics {
    density -1
    mass 100
  }
}
Armchair {
  hidden linearVelocity_0 2.2185695618905166e-17 -5.684341886080802e-17 1.0280336912842534e-16
  hidden angularVelocity_0 2.4337606418672143e-16 5.209321739000572e-18 -6.817419446193141e-17
  translation 2.14 -9.809999999998986e-05 -4.31001
  rotation 1.6656933628650523e-05 0.9999999997225475 1.6656872444432397e-05 1.5708000002774531
  physics Physics {
    density -1
    mass 1
  }
}
Armchair {
  hidden linearVelocity_0 2.8859301692078914e-06 1.1042316846717863e-05 1.5760264420041064e-05
  hidden angularVelocity_0 2.394136857718014e-06 1.895624538628743e-06 -1.538812953659024e-05
  translation 2.1501956510639655 -0.009884251917540832 -6.978951750946033
  rotation 0.0010404103557494888 0.9999985648934865 -0.001337070401777521 -1.570655763324293
  name "armchair(1)"
  physics Physics {
    density -1
    mass 100
  }
}
UnevenTerrain {
  size 20 0 15
  appearance Parquetry {
  }
}
Robot {
  translation 5.488619690147084 0.17392621909567543 -1.100837082030468
  rotation 0.003812676898601901 -0.9999862294234373 -0.003606169486239536 -1.5548349928492138
  children [
    DEF right_behind HingeJoint {
      jointParameters HingeJointParameters {
        position 21.047508047059868
        anchor -0.31 -0.041 0.21
      }
      device [
        RotationalMotor {
          name "wheel1"
        }
      ]
      endPoint Solid {
        translation -0.31 -0.041 0.21
        rotation -0.6654319621771879 0.664902271750874 -0.339271679828341 3.7962483954816335
        children [
          DEF wheel Shape {
            appearance PBRAppearance {
              baseColor 0.9 1 1
            }
            geometry Cylinder {
              height 0.03
              radius 0.16
            }
          }
        ]
        name "wheel3"
        boundingObject USE wheel
        physics Physics {
        }
        linearVelocity 0.021992483212478247 0.0004828634784110765 0.00031437638278594964
        angularVelocity 0.0015673806016542205 -0.00046386230019044607 -0.13941524923809237
      }
    }
    DEF right_back HingeJoint {
      jointParameters HingeJointParameters {
        position 21.047573973819155
        anchor -0.31 -0.041 -0.21
      }
      device [
        RotationalMotor {
          name "wheel2"
        }
      ]
      endPoint Solid {
        translation -0.31 -0.041 -0.21
        rotation -0.6654381983428889 0.6649085029525253 -0.33924723563737685 3.796204525503273
        children [
          DEF wheel Shape {
            appearance PBRAppearance {
              baseColor 0.9 1 1
            }
            geometry Cylinder {
              height 0.03
              radius 0.16
            }
          }
        ]
        name "wheel4"
        boundingObject USE wheel
        physics Physics {
        }
        linearVelocity 0.02198470065247272 0.0018584240697923104 0.0001513157895351855
        angularVelocity 0.0015627798174073484 -0.0004645658016723749 -0.13935040889785466
      }
    }
    DEF left_behind HingeJoint {
      jointParameters HingeJointParameters {
        position 21.10940550122113
        anchor 0.31 -0.041 0.21
      }
      device [
        RotationalMotor {
          name "wheel3"
        }
      ]
      endPoint Solid {
        translation 0.31 -0.041 0.21
        rotation -0.6710513792216288 0.6705172156837438 -0.31638064086866907 3.75488352002654
        children [
          DEF wheel Shape {
            appearance PBRAppearance {
              baseColor 0.9 1 1
            }
            geometry Cylinder {
              height 0.03
              radius 0.16
            }
          }
        ]
        name "wheel2"
        boundingObject USE wheel
        physics Physics {
        }
        linearVelocity 0.022268478438932326 8.138612351283139e-05 0.00031880343685333626
        angularVelocity 0.0015949349157845531 -0.0004640872594350781 -0.14114024130681066
      }
    }
    DEF body Shape {
      appearance PBRAppearance {
      }
      geometry Box {
        size 0.6 0.3 0.7
      }
    }
    DEF left_back HingeJoint {
      jointParameters HingeJointParameters {
        position 21.109471428409993
        anchor 0.31 -0.041 -0.21
      }
      device [
        RotationalMotor {
          name "wheel4"
        }
      ]
      endPoint Solid {
        translation 0.31 -0.041 -0.21
        rotation -0.6710571162691068 0.6705229481644751 -0.31635632234777805 3.7548392793064083
        children [
          DEF wheel Shape {
            appearance PBRAppearance {
              baseColor 0.9 1 1
            }
            geometry Cylinder {
              height 0.03
              radius 0.16
            }
          }
        ]
        name "wheel1"
        boundingObject USE wheel
        physics Physics {
        }
        linearVelocity 0.022260695879471742 0.0014569467152544652 0.00015574279588887366
        angularVelocity 0.001590333753404863 -0.0004648017122129165 -0.14107540097055787
      }
    }
  ]
  name "robot(1)"
  boundingObject USE body
  physics Physics {
  }
  controller "Go"
  linearVelocity 0.022259433802475508 0.0009901858593835836 0.00021016295925034632
  angularVelocity -0.0006069898187784162 -0.00044564335967921666 -0.0033504514811913107
}
Door {
  hidden translation_5 2.77776801560492e-10 -2.220446049250313e-16 0.0010000011651704332
  translation -1.1 0 -4.1
  rotation 0 1 0 3.14159
  name "door(1)"
  size 1.3 2.4 0.2
  position -1.9969465418662205e-08
}
Door {
  hidden translation_5 2.7777724564970185e-10 -2.220446049250313e-16 0.0010000011651721263
  translation -6.6 0 -0.9
  rotation 0 1 0 -1.5707953071795862
  name "door(2)"
  size 1.3 2.4 0.2
  position -1.996946810755607e-08
}
Pedestrian {
  translation 5.03 1.27 -2.84
  rotation 0 -1 0 1.57079
  enableBoundingObject TRUE
}
Solid {
  translation 4.3 0.31 -3.42
  rotation 0.5773509358560258 -0.577349935856137 -0.577349935856137 2.09439
  children [
    Transform {
      children [
        Solid {
          translation -0.02 0.01 0
          children [
            Solid {
              translation 0 0.01 0
              children [
                Shape {
                  appearance PBRAppearance {
                    baseColor 0 0 0
                  }
                  geometry Cylinder {
                    height 0.001
                    radius 0.013
                  }
                }
              ]
            }
            Shape {
              appearance Plaster {
              }
              geometry Cylinder {
                height 0.02
                radius 0.015
              }
            }
          ]
        }
      ]
    }
    Transform {
      translation 0.04 0 0
      children [
        Solid {
          translation -0.02 0.01 0
          children [
            Solid {
              translation 0 0.01 0
              children [
                Shape {
                  appearance PBRAppearance {
                    baseColor 0 0 0
                  }
                  geometry Cylinder {
                    height 0.001
                    radius 0.013
                  }
                }
              ]
            }
            Shape {
              appearance Plaster {
              }
              geometry Cylinder {
                height 0.02
                radius 0.015
              }
            }
          ]
          name "solid(1)"
        }
      ]
    }
    Shape {
      appearance Pcb {
        IBLStrength 2
      }
      geometry Box {
        size 0.1 0.01 0.05
      }
    }
  ]
  name "solid(2)"
}
Solid {
  translation 4.2 0 2.2
  children [
    Shape {
      geometry Box {
        size 0.1 0.1 0.1
      }
    }
  ]
  name "solid(1)"
}
Robot {
  translation -4.410941424515751 0.19857285544676478 -4.500793245283347
  rotation 0.006483345219904614 -0.999960746488477 0.006039181812748732 1.561930407076707
  children [
    DEF zhijia Transform {
    }
    Kinect {
      hidden position_0_0 -4.9998165564802134e-14
      hidden linearVelocity_1 -4.070699386048573e-06 7.006513031981854e-07 1.5291989356491577e-06
      hidden angularVelocity_1 1.1715659296768305e-06 8.878789386398392e-07 3.455427463443259e-06
      translation -1.59216e-07 0.94 -0.24
      rotation 1.7318098054302875e-07 -0.9914448886106625 -0.13052598533533916 -3.1415853071795863
      maxRange 4
    }
    Compass {
      rotation 0 -1 0 1.5708
    }
    DEF lf_taban Transform {
      translation 0.15 0.0153072 0.376956
      rotation 2.663910221101894e-09 0.8314690690111042 0.5555710461118432 3.14159
      children [
        Transform {
          translation 0.05 0.07 0
          children [
            Solid {
              children [
                DEF dd Shape {
                  appearance Leather {
                    colorOverride 0.298039 0.298039 0.298039
                    textureTransform TextureTransform {
                      scale 10 10
                    }
                  }
                  geometry Box {
                    size 0.1 0.18 0.01
                  }
                }
              ]
              name "solid(6)"
              boundingObject USE dd
              physics Physics {
                density -1
                mass 1
              }
            }
          ]
        }
        Shape {
          appearance Leather {
            colorOverride 0.298039 0.298039 0.298039
            textureTransform TextureTransform {
              scale 10 10
            }
          }
          geometry Cylinder {
            height 0.15
            radius 0.01
          }
        }
      ]
    }
    DEF rt_taban Transform {
      translation -0.18 0.0153072 0.376956
      rotation 1 0 0 1.1780996938995747
      children [
        Transform {
          translation 0.05 0.07 0
          children [
            Solid {
              children [
                DEF dd Shape {
                  appearance Leather {
                    colorOverride 0.298039 0.298039 0.298039
                    textureTransform TextureTransform {
                      scale 10 10
                    }
                  }
                  geometry Box {
                    size 0.1 0.18 0.01
                  }
                }
              ]
              name "solid(7)"
              boundingObject USE dd
              physics Physics {
                density -1
                mass 1
              }
            }
          ]
        }
        Shape {
          appearance Leather {
            colorOverride 0.298039 0.298039 0.298039
            textureTransform TextureTransform {
              scale 10 10
            }
          }
          geometry Cylinder {
            height 0.15
            radius 0.01
          }
        }
      ]
    }
    DEF lf_hinge HingeJoint {
      jointParameters HingeJointParameters {
        position 0.0028082199729035696
        axis 0 1 0
        anchor 0.25 -0.06 0.24
      }
      endPoint Solid {
        translation 0.25 -0.06 0.24
        rotation 0 1 0 0.0028082199728544826
        children [
          Transform {
            translation -0.02 -0.0353553 -0.0229291
            rotation 1 0 0 -0.785395307179586
            children [
              Shape {
                appearance CorrugatedPvc {
                }
                geometry Box {
                  size 0.01 0.02 0.09
                }
              }
            ]
          }
          Transform {
            translation 0.02 -0.0353553 -0.0229291
            rotation 1 0 0 -0.785395307179586
            children [
              Shape {
                appearance CorrugatedPvc {
                }
                geometry Box {
                  size 0.01 0.02 0.09
                }
              }
            ]
          }
          HingeJoint {
            jointParameters HingeJointParameters {
              position 214.18459722127605
              anchor 0.02 -0.07 -0.05
            }
            endPoint Solid {
              translation -3.469446951953614e-17 -0.07 -0.05
              rotation 0.26477566812629827 -0.26477611184178756 0.9272472465131497 1.6462610570641938
              children [
                DEF wheel Shape {
                  appearance TireRubber {
                    textureTransform TextureTransform {
                      rotation 1
                      scale 5 21
                      translation 5 24
                    }
                  }
                  geometry Cylinder {
                    height 0.005
                    radius 0.075
                  }
                }
              ]
              boundingObject USE wheel
              physics Physics {
                density -1
                mass 1
              }
              linearVelocity 2.9303004883215544e-08 -9.429131711127813e-07 -1.054629038355256e-07
              angularVelocity 9.637960071649084e-07 1.438108968905638e-05 -4.0983677837310354e-07
            }
          }
          DEF lf_hinge Shape {
            appearance PBRAppearance {
              baseColor 0 0 0
            }
            geometry Cylinder {
              height 0.02
              radius 0.01
            }
          }
        ]
        name "wheel1"
        boundingObject USE lf_hinge
        physics Physics {
          density -1
          mass 1
        }
        linearVelocity -2.0302145212665324e-07 -1.1384888816223793e-06 6.954307315456543e-07
        angularVelocity 1.003396720761236e-06 1.4379659409147754e-05 3.4631380844950433e-06
      }
    }
    DEF rt_hinge HingeJoint {
      jointParameters HingeJointParameters {
        position -0.0042319398260612364
        axis 0 1 0
        anchor -0.25 -0.06 0.24
      }
      endPoint Solid {
        translation -0.25 -0.06 0.24
        rotation 0 -1 0 0.0042319398260374265
        children [
          Transform {
            translation 0.02 -0.0353553 -0.0229291
            rotation 1 0 0 -0.785395307179586
            children [
              Shape {
                appearance CorrugatedPvc {
                }
                geometry Box {
                  size 0.01 0.02 0.09
                }
              }
            ]
          }
          Transform {
            translation -0.02 -0.0353553 -0.0229291
            rotation 1 0 0 -0.785395307179586
            children [
              Shape {
                appearance CorrugatedPvc {
                }
                geometry Box {
                  size 0.01 0.02 0.09
                }
              }
            ]
          }
          HingeJoint {
            jointParameters HingeJointParameters {
              position 205.18518956390335
              anchor 0.02 -0.07 -0.05
            }
            endPoint Solid {
              translation 5.494480000006741e-07 -0.07 -0.05
              rotation 0.6614473065827735 -0.6614478099923561 -0.35351698017310357 3.821201116865638
              children [
                DEF wheel Shape {
                  appearance TireRubber {
                    textureTransform TextureTransform {
                      rotation 1
                      scale 5 21
                      translation 5 24
                    }
                  }
                  geometry Cylinder {
                    height 0.005
                    radius 0.075
                  }
                }
              ]
              boundingObject USE wheel
              physics Physics {
                density -1
                mass 1
              }
              linearVelocity -4.152675628795842e-07 -3.94513869305161e-07 -9.658809467540018e-08
              angularVelocity 1.0259391608765507e-06 1.4284720491324773e-05 5.518345428767532e-06
            }
          }
          DEF lf_hinge Shape {
            appearance PBRAppearance {
              baseColor 0 0 0
            }
            geometry Cylinder {
              height 0.02
              radius 0.01
            }
          }
        ]
        name "wheel2"
        boundingObject USE lf_hinge
        physics Physics {
          density -1
          mass 1
        }
        linearVelocity -6.476113295379101e-07 -5.790863792185519e-07 6.996041543236852e-07
        angularVelocity 1.0045647178157189e-06 1.4285496078584039e-05 3.462535502969993e-06
      }
    }
    InertialUnit {
      translation 8.81572e-07 0.25 -0.24
      rotation 0 -1 0 1.5708
      children [
        Shape {
          appearance PBRAppearance {
          }
          geometry Box {
            size 0.1 0.1 0.1
          }
        }
      ]
      name "imu"
      xAxis FALSE
      zAxis FALSE
    }
    Display {
      width 60
      height 50
    }
    Transform {
      translation -0.2 0.15 0.24
      children [
        Shape {
          appearance Leather {
            colorOverride 1 1 0.498039
            textureTransform TextureTransform {
              scale 10 10
            }
            IBLStrength 12
          }
          geometry Box {
            size 0.05 0.2 0.05
          }
        }
      ]
    }
    Transform {
      translation 0.2 0.15 0.24
      children [
        Shape {
          appearance Leather {
            colorOverride 1 1 0.498039
            textureTransform TextureTransform {
              scale 10 10
            }
            IBLStrength 12
          }
          geometry Box {
            size 0.05 0.2 0.05
          }
        }
      ]
    }
    Transform {
      translation 0.22 0.33 0.07
      children [
        Shape {
          appearance Leather {
            colorOverride 1 1 0.498039
            textureTransform TextureTransform {
              scale 10 10
            }
            IBLStrength 12
          }
          geometry Box {
            size 0.05 0.3 0.05
          }
        }
      ]
    }
    Transform {
      translation 0.22 0.48 -0.08
      children [
        Shape {
          appearance Leather {
            colorOverride 1 1 0.498039
            textureTransform TextureTransform {
              scale 10 10
            }
            IBLStrength 12
          }
          geometry Box {
            size 0.05 0.1 0.4
          }
        }
      ]
    }
    Transform {
      translation -0.22 0.47 -0.08
      children [
        Shape {
          appearance Leather {
            colorOverride 1 1 0.498039
            textureTransform TextureTransform {
              scale 10 10
            }
            IBLStrength 12
          }
          geometry Box {
            size 0.05 0.1 0.4
          }
        }
      ]
    }
    Transform {
      translation -0.22 0.34 0.07
      children [
        Shape {
          appearance Leather {
            colorOverride 1 1 0.498039
            textureTransform TextureTransform {
              scale 10 10
            }
            IBLStrength 12
          }
          geometry Box {
            size 0.05 0.2 0.05
          }
        }
      ]
    }
    Transform {
      translation 0 0.22 0
      children [
        Solid {
          children [
            DEF zuo Shape {
              appearance Leather {
                colorOverride 1 1 0.498039
                textureTransform TextureTransform {
                  scale 10 10
                }
                IBLStrength 12
              }
              geometry Box {
                size 0.5 0.1 0.6
              }
            }
          ]
          name "solid(5)"
          boundingObject USE zuo
          physics Physics {
            density -1
            mass 1
          }
        }
      ]
    }
    Transform {
      translation 0 0.49 -0.26
      children [
        Solid {
          children [
            DEF back Shape {
              appearance Leather {
                colorOverride 1 1 0.498039
                textureTransform TextureTransform {
                  scale 10 10
                }
                IBLStrength 12
              }
              geometry Box {
                size 0.5 0.9 0.1
              }
            }
          ]
          name "solid(4)"
          boundingObject USE back
          physics Physics {
            density -1
            mass 1
          }
        }
      ]
    }
    GPS {
      translation 0 0.1 0
      children [
        Solid {
          children [
            Shape {
              appearance PBRAppearance {
              }
              geometry Cone {
                bottomRadius 0.05
                height 0.1
              }
            }
          ]
        }
      ]
    }
    DistanceSensor {
      translation -0.214629 0 0.299397
      rotation 0 1 0 -1.5707953071795862
      children [
        DEF ds_right Shape {
          geometry Box {
            size 0.02 0.02 0.02
          }
        }
      ]
      name "ds_right"
      boundingObject USE ds_right
      physics Physics {
        density -1
        mass 1
      }
      lookupTable [
        0 1000 0
        0.5 200 0.1
        1 100 0.1
        1.5 40 0
        2 30 0
      ]
      type "sonar"
      numberOfRays 8
      aperture 0.16
    }
    DistanceSensor {
      translation 0.224288 0 0.296809
      rotation 0 -1 0 1.309
      children [
        DEF ds_right Shape {
          geometry Box {
            size 0.02 0.02 0.02
          }
        }
      ]
      name "ds_left"
      boundingObject USE ds_right
      physics Physics {
        density -1
        mass 1
      }
      lookupTable [
        0 1000 0
        0.5 200 0.1
        1 100 0.1
        1.5 40 0
        2 30 0
      ]
      type "sonar"
      numberOfRays 8
      aperture 0.16
    }
    DistanceSensor {
      translation 0.161668 0 0.311629
      rotation 0 -1 0 0.785396
      children [
        DEF ds_right Shape {
          geometry Box {
            size 0.02 0.02 0.02
          }
        }
      ]
      name "ds_left_1"
      boundingObject USE ds_right
      physics Physics {
        density -1
        mass 1
      }
      lookupTable [
        0 1000 0
        0.5 200 0.1
        1 100 0.1
        1.5 40 0
        2 30 0
      ]
      type "sonar"
      numberOfRays 8
      aperture 0.16
    }
    DEF left_back HingeJoint {
      jointParameters HingeJointParameters {
        position 124.86163305580796
        anchor 0.28 -0.073 -0.2
      }
      device [
        RotationalMotor {
          name "motor3"
          maxVelocity 15
        }
      ]
      endPoint Solid {
        translation 0.28 -0.073 -0.2
        rotation 0.36456846592239 -0.36456969323103927 -0.8568423264711081 4.558495324931737
        children [
          DEF wheel Shape {
            appearance TireRubber {
              textureTransform TextureTransform {
                rotation 42
                scale 0 0
              }
              IBLStrength 2
              type "bike"
            }
            geometry Cylinder {
              height 0.05
              radius 0.13
            }
          }
        ]
        name "wheel3"
        boundingObject USE wheel
        physics Physics {
          density -1
          mass 1
        }
        linearVelocity -1.5311660534065524e-07 3.2725437309053724e-07 2.951865818014541e-07
        angularVelocity 1.1709313425221343e-06 8.879070644017861e-07 3.3812978744054826e-06
      }
    }
    DEF right_back HingeJoint {
      jointParameters HingeJointParameters {
        position 104.51329256377277
        anchor -0.28 -0.073 -0.2
      }
      device [
        RotationalMotor {
          name "motor4"
          maxVelocity 15
        }
      ]
      endPoint Solid {
        translation -0.28 -0.073 -0.2
        rotation -0.6743125590617387 0.6743148294159357 0.30100179986399883 2.5568432657499596
        children [
          DEF wheel Shape {
            appearance TireRubber {
              textureTransform TextureTransform {
                rotation 42
                scale 0 0
              }
              IBLStrength 2
              type "bike"
            }
            geometry Cylinder {
              height 0.05
              radius 0.13
            }
          }
        ]
        name "wheel4"
        boundingObject USE wheel
        physics Physics {
          density -1
          mass 1
        }
        linearVelocity -6.505976472692862e-07 9.535431603952665e-07 2.9986563744357797e-07
        angularVelocity 1.1720444952151223e-06 8.878586861779961e-07 3.5064146942639416e-06
      }
    }
    DEF body Shape {
      appearance Leather {
        colorOverride 1 1 0.498039
        textureTransform TextureTransform {
          scale 10 10
        }
        IBLStrength 12
      }
      geometry Box {
        size 0.5 0.1 0.6
      }
    }
  ]
  boundingObject USE body
  physics Physics {
    density -1
    mass 1
  }
  controller "my_controller1"
  linearVelocity -1.1045733847665707e-06 -6.609980907580307e-07 8.734099647713021e-07
  angularVelocity 1.1715659252243444e-06 8.878789374947204e-07 3.455427028284475e-06
}
DEF Humman Solid {
  translation -4.313627015324938 0.719715440343468 -4.493452760035947
  rotation -0.1073801290228162 -0.9890265096533165 -0.10146955747425619 1.610270591409403
  children [
    DEF rt_leg Transform {
      children [
        Solid {
          translation -0.0996593 -0.229576 0.176128
          rotation -1 -4.29919e-07 -7.83179e-08 -1.7017053071795862
          children [
            DEF rt_leg Shape {
              appearance ShinyLeather {
                colorOverride 1 0.666667 0.498039
                textureTransform TextureTransform {
                  scale 0 0
                }
                IBLStrength 10
              }
              geometry Cylinder {
                height 0.4
                radius 0.04
              }
            }
          ]
          name "solid(2)"
          boundingObject USE rt_leg
          physics Physics {
            density -1
            mass 1
          }
        }
      ]
    }
    DEF rt_arm_xiao Transform {
      translation 0 0.2 0
      children [
        Solid {
          translation -0.209659 -0.176251 0.041941
          rotation 1 3.6511e-07 -2.98616e-08 2.2253
          children [
            DEF rt_leg Shape {
              appearance ShinyLeather {
                colorOverride 1 0.666667 0.498039
                textureTransform TextureTransform {
                  scale 0 0
                }
                IBLStrength 10
              }
              geometry Cylinder {
                height 0.2
                radius 0.03
              }
            }
          ]
          name "solid(8)"
          boundingObject USE rt_leg
          physics Physics {
            density -1
            mass 1
          }
        }
      ]
    }
    DEF rt_arm_xiao Transform {
      translation 0.43 0.2 0
      children [
        Solid {
          translation -0.209659 -0.176251 0.041941
          rotation 1 3.6511e-07 -2.98616e-08 2.2253
          children [
            DEF rt_leg Shape {
              appearance ShinyLeather {
                colorOverride 1 0.666667 0.498039
                textureTransform TextureTransform {
                  scale 0 0
                }
                IBLStrength 10
              }
              geometry Cylinder {
                height 0.2
                radius 0.03
              }
            }
          ]
          name "solid(9)"
          boundingObject USE rt_leg
          physics Physics {
            density -1
            mass 1
          }
        }
      ]
    }
    DEF lf_leg Transform {
      translation 0.15 0 0
      children [
        Solid {
          translation -0.0417035 -0.228224 0.165864
          rotation 1 5.7759e-07 4.66287e-07 1.7017
          children [
            DEF rt_leg Shape {
              appearance ShinyLeather {
                colorOverride 1 0.666667 0.498039
                textureTransform TextureTransform {
                  scale 0 0
                }
                IBLStrength 10
              }
              geometry Cylinder {
                height 0.4
                radius 0.04
              }
            }
          ]
          name "solid(3)"
          boundingObject USE rt_leg
          physics Physics {
            density -1
            mass 1
          }
        }
      ]
    }
    DEF lf_leg_xiao Transform {
      translation 0.16 -0.11 0.31
      children [
        Solid {
          translation -0.0517035 -0.29358 0.0500802
          rotation 1 5.56149e-07 -5.92991e-08 -3.0106853071795863
          children [
            Transform {
              translation 0 0.157753 -0.0370711
              rotation 1 0 0 -0.261795307179586
              children [
                Solid {
                  children [
                    DEF rt_leg111 Shape {
                      appearance ShinyLeather {
                        colorOverride 1 0.666667 0.498039
                        textureTransform TextureTransform {
                          scale 0 0
                        }
                        IBLStrength 10
                      }
                      geometry Box {
                        size 0.1 0.05 0.13
                      }
                    }
                  ]
                  boundingObject USE rt_leg111
                  physics Physics {
                    density -1
                    mass 1
                  }
                }
              ]
            }
            DEF rt_leg Shape {
              appearance ShinyLeather {
                colorOverride 1 0.666667 0.498039
                textureTransform TextureTransform {
                  scale 0 0
                }
                IBLStrength 10
              }
              geometry Cylinder {
                height 0.28
                radius 0.04
              }
            }
            DEF rt_leg Shape {
              appearance ShinyLeather {
                colorOverride 1 0.666667 0.498039
                textureTransform TextureTransform {
                  scale 0 0
                }
                IBLStrength 10
              }
              geometry Cylinder {
                height 0.28
                radius 0.04
              }
            }
          ]
          name "solid(4)"
          boundingObject USE rt_leg
          physics Physics {
            density -1
            mass 1
          }
        }
      ]
    }
    DEF lf_leg_xiao Transform {
      translation -0.05 -0.12 0.31
      children [
        DEF lf_leg_xiao Transform {
          translation 0.16 -0.11 0.31
          children [
            Solid {
              translation -0.241703 -0.173813 -0.24682
              rotation 1 5.56149e-07 -5.92991e-08 -3.0106853071795863
              children [
                Transform {
                  translation 0 0.157753 -0.0370711
                  rotation 1 0 0 -0.261795307179586
                  children [
                    Solid {
                      children [
                        DEF rt_leg222 Shape {
                          appearance ShinyLeather {
                            colorOverride 1 0.666667 0.498039
                            textureTransform TextureTransform {
                              scale 0 0
                            }
                            IBLStrength 10
                          }
                          geometry Box {
                            size 0.1 0.05 0.13
                          }
                        }
                      ]
                      boundingObject USE rt_leg222
                      physics Physics {
                        density -1
                        mass 1
                      }
                    }
                  ]
                }
                DEF rt_leg Shape {
                  appearance ShinyLeather {
                    colorOverride 1 0.666667 0.498039
                    textureTransform TextureTransform {
                      scale 0 0
                    }
                    IBLStrength 10
                  }
                  geometry Cylinder {
                    height 0.28
                    radius 0.04
                  }
                }
                DEF rt_leg Shape {
                  appearance ShinyLeather {
                    colorOverride 1 0.666667 0.498039
                    textureTransform TextureTransform {
                      scale 0 0
                    }
                    IBLStrength 10
                  }
                  geometry Cylinder {
                    height 0.28
                    radius 0.04
                  }
                }
              ]
              name "solid(5)"
              boundingObject USE rt_leg
              physics Physics {
                density -1
                mass 1
              }
            }
          ]
        }
      ]
    }
    DEF pigu Transform {
      translation -1.68355e-07 -0.21 0
      rotation 0 0 1 1.5707996938995747
      children [
        DEF pg Solid {
          children [
            DEF pigu Shape {
              appearance ShinyLeather {
                colorOverride 1 0.666667 0.498039
                textureTransform TextureTransform {
                  scale 0 0
                }
                IBLStrength 10
              }
              geometry Cylinder {
                height 0.15
                radius 0.05
              }
            }
          ]
          name "solid(1)"
          boundingObject USE pigu
          physics Physics {
            density -1
            mass 1
          }
        }
      ]
    }
    DEF rt_arm Transform {
      translation -0.110001 0.08 0
      rotation 0 0 1 1.5707996938995747
      children [
        DEF pg Solid {
          translation 0 0.01 0
          children [
            DEF pigu Shape {
              appearance ShinyLeather {
                colorOverride 1 0.666667 0.498039
                textureTransform TextureTransform {
                  scale 0 0
                }
                IBLStrength 10
              }
              geometry Cylinder {
                height 0.23
                radius 0.03
              }
            }
          ]
          name "solid(6)"
          boundingObject USE pigu
          physics Physics {
            density -1
            mass 1
          }
        }
      ]
    }
    DEF rt_arm Transform {
      translation 0.089999 0.08 0
      rotation 0 0 1 1.5707996938995747
      children [
        DEF pg Solid {
          translation 0 -0.02 0
          children [
            DEF pigu Shape {
              appearance ShinyLeather {
                colorOverride 1 0.666667 0.498039
                textureTransform TextureTransform {
                  scale 0 0
                }
                IBLStrength 10
              }
              geometry Cylinder {
                height 0.23
                radius 0.03
              }
            }
          ]
          name "solid(7)"
          boundingObject USE pigu
          physics Physics {
            density -1
            mass 1
          }
        }
      ]
    }
    DEF head Transform {
      children [
        DEF Head Solid {
          translation 0 0.29 0
          children [
            DEF head Shape {
              appearance ShinyLeather {
                colorOverride 1 0.666667 0.498039
                textureTransform TextureTransform {
                  scale 0 0
                }
                IBLStrength 10
              }
              geometry Sphere {
                radius 0.12
              }
            }
          ]
        }
      ]
    }
    DEF body Shape {
      appearance ShinyLeather {
        colorOverride 1 0.666667 0.498039
        textureTransform TextureTransform {
          scale 0 0
        }
        IBLStrength 10
      }
      geometry Cylinder {
        height 0.4
        radius 0.05
      }
    }
  ]
  name "solid(4)"
  boundingObject USE body
  physics Physics {
    density -1
    mass 1
  }
  linearVelocity -4.6041477743386845e-05 -2.136594244476934e-05 3.1689872396063614e-05
  angularVelocity 4.589376689253155e-06 -0.00014989225011001177 -0.00011980979437491976
}
